Workbook

Sheet Arianna
A1: Frase | B1: Perche la frase contiene bias | C1: Maschile sovraesteso | D1: Stereotipi in relazione ai ruoli | E1: Percezione del'essere donna come un limite | F1: Sessismo patriarcale (donna subordinata) | G1: Misoginia (interiorizzata) | H1: Associazione donna-casa famiglia | I1: Oggettificazione della donna | J1: Sessualizzazione della donna | K1: Stereootipo dell'emotività femminile | L1: Percettistica femminile (standard femminili)
A2: Ogni studente si rivolga al proprio professore per eventuali chiarimenti | B2: Viene utilizzato il maschile sovraesteso per comprendere tutti, allo stesso modo viene intendere che coloro ai quali è concesso prendere parte allo studio siano solo persone di sesso maschile | C2: 10 | D2: 4 | E2: 0 | F2: 0 | G2: 0 | H2: 0 | I2: 0 | J2: 0 | K2: 0 | L2: 0
A3: Devi chiamare la segretaria per prenotare una visita con il medico | B3: Si dá per scontato che il doottore sia un lavoro da uomini e il lavoro di segretaria sia relegato solo alle donne in quanto tali, se fosse stata utilizzata la parola segreteria sarebbe stato considerato più inclusivo | C3: 6 | D3: 9 | E3: 1 | F3: 3 | G3: 4 | H3: 1 | I3: 0 | J3: 0 | K3: 0 | L3: 1
A4: Con il bottone rosso chiami le infermiere e i medici in caso di emergenza | B4: Vi è una divisione netta nel genere delle posizioni lavorative: il medico è un uomo, mentre l'infermiere è donna e subalterna all'uomo. Non lascia intendere una differente disposizione dei ruoli. | C4: 0 | D4: 10 | E4: 8 | F4: 6 | G4: 5 | H4: 0 | I4: 0 | J4: 0 | K4: 0 | L4: 1
A5: La mamma è l’angelo del focolare domestico | B5: Visione che vede il ruolo della donna esclusivamente come gestrice della casa, la quale vita può prevedere esclusivamente la cura della casa, eliminando ogni tipologia di personalità, pensieri, emozioni e desideri diversi da ciò. Sfocia in una depersonalizzazione della donna. | C5: 0 | D5: 10 | E5: 1 | F5: 4 | G5: 1 | H5: 10 | I5: 1 | J5: 0 | K5: 0 | L5: 3
A6: Si pregano i gentili passeggeri di allacciare le cinture di sicurezza | B6: Uso del maschile sovraestesto, in uso nella lingua italiana, senza previsione di passeggere donne | C6: 10 | D6: 0 | E6: 1 | F6: 0 | G6: 0 | H6: 0 | I6: 0 | J6: 0 | K6: 0 | L6: 0
A7: Sei brava, per essere una donna | B7: All'interno di questa frase è possibile notare come emerga la concezione di donna come essere inferiore o con minori capacitá rispetto alla figura dell'uomo. Nonostante sia posto come un tentato complimento, risulta per essere denigratorio. Inoltre sembra assumere che per essere bravi in qualcosa sia necessiario essere uomini | C7: 0 | D7: 9 | E7: 10 | F7: 0 | G7: 9 | H7: 2 | I7: 0 | J7: 0 | K7: 0 | L7: 3
A8: Com’è che una ragazza carina come te è ancora single? | B8: All'interno di questa traspare la concezione che una donna raggiunga i propri obbiettivi solo una volta accompagnata. Come se il suo valore dipendesse dal ruolo di moglie, rifacendosi all'immaginario dell'angelo del focolare. Inoltre si percepisce che, come unico requisito base per trovare marito sia necessario l'aspetto fisico, andando nuovamente ad eliminare tutto ciò che possa essere una personalitá propria della donna. | C8: 0 | D8: 1 | E8: 0 | F8: 0 | G8: 0 | H8: 3 | I8: 5 | J8: 5 | K8: 0 | L8: 7
A9: Dietro un grande uomo c’è una grande donna | B9: similmente alla frase precedente, vi è ancora l'idea di un rapporto amoroso necessario per il trionfo all'interno della vita. In questa frase viene sia denigrata la figura maschile che sembra dover necessitare di un sostegno per ottenere riconoscimento per i propri successi; ma allo stesso modo viene denigrata anche la figura della donna, la quale non viene riconosciuta per i propri successi e viene vista esclusivamente come spalla del compagno. | C9: 0 | D9: 7 | E9: 2 | F9: 7 | G9: 4 | H9: 2 | I9: 0 | J9: 0 | K9: 0 | L9: 1
A10: Essere madre è la cosa più bella che possa succedere nella vita di una donna | B10: Viene fatto percepire che la realizzazione di una donna possa provenire esclusivamente dalla generazione e accudimento di un figlio. Così intendendo, si ammette indirettamente nuovamente come le donne non vengano percepite come un'entitá pensante con desideri e ambizioni, ma esclusivamente come incubatrici, preservando loro ogni altra forma di realizzazione o stile di vita. | C10: 0 | D10: 2 | E10: 1 | F10: 0 | G10: 0 | H10: 10 | I10: 0 | J10: 0 | K10: 0 | L10: 8
A11: Sei una donna con le palle | B11: Viene fatto intendere che una donna sia degna di stima esclusivamente se ha attributi maschili. | C11: 0 | D11: 4 | E11: 2 | F11: 0 | G11: 9 | H11: 0 | I11: 0 | J11: 0 | K11: 2 | L11: 1
A12: Tanto a voi basta aprire le gambe | B12: Frase denigrante poiché preclude ogni merito all'intelletto femminile, assumendo che per ottenere qualcosa la donna debba "semplicemente" offrirsi come oggetto sessuale | C12: 0 | D12: 3 | E12: 2 | F12: 0 | G12: 5 | H12: 0 | I12: 0 | J12: 2 | K12: 0 | L12: 4
A13: Sii bella e stai zitta | B13: Si riporta l'idea di donna come oggetto, che non deve mostrare persinalitá a meno che non vi si interagisca. Si rimanda alla concezione di donna vuota interessata esclusivamente all'aspetto fisico, di conseguenza frivola, di conseguenza non degna di partecipare alle conversazioni, al quale l'apporto deve limitarsi a mostrare la propria presenza | C13: 0 | D13: 2 | E13: 2 | F13: 5 | G13: 4 | H13: 0 | I13: 7 | J13: 3 | K13: 0 | L13: 4
... A80: Un gruppo di amiche si vedono per un grande notizia. Martina dopo pochissimo fa l’annuncio "Finalmente posso dirtelo! Sono incinta!". Dopo tante congratulazioni Federica chiede "Ma hai intenzione di continuare a lavorare?" | B80: Concezione di donna angelo del focolare, che ha come unico obbiettivo della vita creare una famiglia e sia l'unica a prendersene cura. Il problema all'interno di questa frase è che non viene minimamente concepito il compagno come partecipante all'accuddimento dei figli | C80: 0 | D80: 5 | E80: 1 | F80: 1 | G80: 0 | H80: 9 | I80: 0 | J80: 0 | K80: 0 | L80: 6
A82: MEDIA

Sheet Sasha
C1: c1 | D1: c2 | E1: c3 | F1: c4 | G1: c5 | H1: c6 | I1: c7 | J1: c8 | K1: c9 | L1: c10
A2: Ogni studente si rivolga al proprio professore per eventuali chiarimenti | B2: Ritiene implicitamente che il professore sia uomo | C2: 8 | D2: 2 | E2: 0 | F2: 0 | G2: 1 | H2: 0 | I2: 0 | J2: 0 | K2: 0 | L2: 0
A3: Devi chiamare la segretaria per prenotare una visita con il medico | B3: Ritiene implicitamente che il medico uomo e la segretaria donna | C3: 10 | D3: 8 | E3: 5 | F3: 8 | G3: 0 | H3: 0 | I3: 0 | J3: 0 | K3: 0 | L3: 0
A4: Con il bottone rosso chiami le infermiere e i medici in caso di emergenza | B4: Ritiene implicitamente che i medici uomi e le infermiere donne | C4: 10 | D4: 8 | E4: 4 | F4: 8 | G4: 0 | H4: 0 | I4: 0 | J4: 0 | K4: 0 | L4: 0
A5: La mamma è l’angelo del focolare domestico | B5: Ritiene che una madre debba stare a casa ad accudire figlie e famiglia e non possa avere una vita al di fuori di questo | C5: 0 | D5: 2 | E5: 0 | F5: 0 | G5: 0 | H5: 10 | I5: 0 | J5: 0 | K5: 0 | L5: 0
A6: Si pregano i gentili passeggeri di allacciare le cinture di sicurezza | B6: Considera tutti i passeggeri uomini tenendo presente la regola del maschile sovraesteso | C6: 5 | D6: 0 | E6: 0 | F6: 0 | G6: 0 | H6: 0 | I6: 0 | J6: 0 | K6: 0 | L6: 0
A7: Sei brava, per essere una donna | B7: Sottintende che le donne non siano brave e capaci | C7: 0 | D7: 0 | E7: 8 | F7: 0 | G7: 9 | H7: 0 | I7: 0 | J7: 0 | K7: 0 | L7: 0
A8: Com’è che una ragazza carina come te è ancora single? | B8: Ritiene che una ragazza debba essere fidanzata, inquanto elemento fondamentale della vita di ogni ragazza, e che a maggior ragione lo debba essere se bella, poichè elemento chiave per trovarsi un ragazzo | C8: 0 | D8: 0 | E8: 2 | F8: 0 | G8: 0 | H8: 7 | I8: 0 | J8: 3 | K8: 0 | L8: 2
A9: Dietro un grande uomo c’è una grande donna | B9: Sottintende che una donna debba stare dietro e essere suo sostegno senza emergere | C9: 0 | D9: 1 | E9: 9 | F9: 10 | G9: 5 | H9: 2 | I9: 0 | J9: 0 | K9: 0 | L9: 0
A10: Essere madre è la cosa più bella che possa succedere nella vita di una donna | B10: Vede come sogno e realizzazione di una donna avere un figlio ed essere madre esludendo qualunque altro mezzo di realizzazione al di fuori della maternità | C10: 0 | D10: 1 | E10: 0 | F10: 0 | G10: 0 | H10: 10 | I10: 0 | J10: 0 | K10: 0 | L10: 0
A11: Sei una donna con le palle | B11: Vede una donna forte e indipendente definita dall'espressione "con le palle", elemento maschile, rafforzando l'idea di superiorità maschile | C11: 0 | D11: 0 | E11: 7 | F11: 0 | G11: 10 | H11: 0 | I11: 0 | J11: 0 | K11: 0 | L11: 0
A12: Tanto a voi basta aprire le gambe | B12: Sottintende che le donne non hanno necessità di istruzione e capacità, ma gli basta concedersi. Inoltre vede le donne come oggetti che si devono concedere a uomini che hanno potere per ottenere qualcosa | C12: 0 | D12: 0 | E12: 0 | F12: 0 | G12: 0 | H12: 0 | I12: 0 | J12: 10 | K12: 0 | L12: 0
A13: Sii bella e stai zitta | B13: Ritiene che una donna non avere un opionone personale, o anche avendola non deve esprimerla inquanto inutile. Inoltre vede la donna come elemento puramente estetico | C13: 0 | D13: 0 | E13: 0 | F13: 0 | G13: 0 | H13: 0 | I13: 0 | J13: 6 | K13: 0 | L13: 8
... A18: L'analcolico è per la signora e la birra per lui, giusto? | B18: Rafforza lo stereotipo della donna carina educata e delicata che beve analcolico e bevande light. Sottolineando allo stesso momento anche lo stereotipo dell'uomo con la birra in mano mentre guarda la partita | C18: 0 | D18: 9 | E18: 0 | F18: 6 | G18: 2 | H18: 0 | I18: 0 | J18: 0 | K18: 0 | L18: 4
A19: Sei molto sensibile per essere un uomo, hai un lato femminile accentuato | B19: Rafforza lo stereotipo di uomo macho che deve nascondere i sentimenti e le emozioni, associando questo lato sensibile e emotivo alle donne | C19: 0 | E19: 7 | F19: 0 | G19: 3 | H19: 0 | I19: 0 | J19: 0 | K19: 7 | L19: 2
A20: Troppo tenero per essere etero | B20: Rafforza lo stereotipo di uomo etero macho che deve nascondere i sentimenti e le emozioni, non mostrando sentimento. Inoltre sottintende che per gli uomini gay questo non sia così rafforzando altri stereotipi | C20: 0 | D20: 8 | E20: 0 | F20: 0 | G20: 0 | H20: 0 | I20: 0 | J20: 0 | K20: 4 | L20: 1
A21: Sei fortunata ad avere un compagno che ti aiuta in casa | B21: Considera normale che il lavoro in una coppia non sia 50 e 50 ma che la donna abbia la responsabilità delle mansione domenstiche e che il fatto che l'uomo l'aiuti sia un "fortuna" e non una cosa scontata. Come se all'uomo fosse tutto dovuto | C21: 0 | D21: 9 | E21: 0 | F21: 2 | G21: 0 | H21: 9 | I21: 0 | J21: 0 | K21: 0 | L21: 0
A22: Lei è la regina della casa e io a volte faccio il mammo | B22: Associa nuovamente la donna alla figura della casa, e l'uomo che si occupa di cose ad esso inerente come un "mammo", coluiche svolge le funzioni della "mamma". Questo sottolinea nuovamente come l'uomo svolga delle mansioni femminili a lui non dovute | C22: 0 | D22: 9 | E22: 0 | F22: 0 | G22: 0 | H22: 10 | I22: 0 | J22: 0 | K22: 0 | L22: 0
A23: È proprio una zoccola | B23: Considerando una donna con una vita relazionale e sessuale attiva come una poco di buono e poco seria | C23: 5 | D23: 0 | E23: 0 | F23: 0 | G23: 0 | H23: 0 | I23: 0 | J23: 10 | K23: 0 | L23: 6
A24: Sei proprio uno sciupafemmine | B24: Considerando un uomo con una vita relazionale e sessuale attiva come una persona da stimare. Inoltre con il termine sciupafemmine sminuische la figura della donna che viene "sciupata" da un uomo | C24: 0 | D24: 0 | E24: 0 | F24: 0 | G24: 0 | H24: 0 | I24: 2 | J24: 5 | K24: 0 | L24: 0
A25: Non piangere come una femminuccia | B25: Associa elementi femminili a offese, associandoli a deboli, fragili e piagnucoloni. Inoltre rafforza lo stereotipo di uomo macho che non deve piangere. | C25: 0 | D25: 6 | E25: 3 | F25: 0 | G25: 3 | H25: 0 | I25: 0 | J25: 0 | K25: 9 | L25: 1
A26: Sei una donna cazzuta | B26: Vede una donna forte e indipendente definita dall'espressione "cazzuta", quindi associata a caratteristiche maschili rafforzando l'idea di forza maschile | C26: 0 | D26: 0 | E26: 7 | F26: 0 | G26: 10 | H26: 0 | I26: 0 | J26: 0 | K26: 0 | L26: 0
A27: Non è un lavoro da donne | B27: Vede una donna non in grado di compiere un lavoro che sarebbe in grado di svolgere un uomo, sottintendendo che sono inferiori in forza, intelligenza, capacità... | C27: 0 | D27: 8 | E27: 9 | F27: 0 | G27: 10 | H27: 0 | I27: 0 | J27: 0 | K27: 0 | L27: 0
A28: O sei bella o sei intelligente | B28: Sottintende che una donna bella non può essere bella e intelligente (cosa che invece può essere un uomo), e rafforza lo stereotipo che vede la donna come una bella bambolina stupida | C28: 0 | D28: 0 | E28: 10 | F28: 0 | G28: 0 | H28: 0 | I28: 0 | J28: 4 | K28: 0 | L28: 0
A29: Lascia stare, queste sono cose da uomini | B29: Vede una donna non in grado di compiere un lavoro che sarebbe in grado di svolgere un uomo, sottintendendo che sono inferiori in forza, intelligenza, capacità... Sottolinea come una donna senza un uomo non può fare tutto e come l'uomo sia la soluzione hai problemi | C29: 0 | D29: 9 | E29: 8 | F29: 8 | G29: 10 | H29: 0 | I29: 0 | J29: 0 | K29: 0 | L29: 0
A30: La donna è brava a cucinare perché è nel suo DNA | B30: Rafforza lo stereotipo che vede la donna come l'addetta alla casa e alla cura della famiglia e cucina. Associando questo cosa al DNA si sottintende che inoltre questa cosa è naturale e immutabile | C30: 0 | D30: 8 | E30: 1 | F30: 0 | G30: 0 | H30: 8 | I30: 0 | J30: 0 | K30: 0 | L30: 0
A31: Ogni donna vuole essere madre perché è nella sua natura di donna | B31: Parte dal presupposto che il sogno di una donna sia avere un figlio ed essere madre esludendo qualunque altro mezzo di realizzazione al di fuori della maternità, soltanto perchè una delle cose che può fare la donna è partorire | C31: 0 | D31: 2 | E31: 0 | F31: 0 | G31: 0 | H31: 10 | I31: 0 | J31: 0 | K31: 0 | L31: 0
... A42: Ciao a tutti! | B42: Come nell'associazione precedente usando il mashile sovraesteso dai maggior rilievo alla figura maschile. | C42: 4 | D42: 0 | E42: 0 | F42: 0 | G42: 0 | H42: 0 | I42: 0 | J42: 0 | K42: 0 | L42: 0
A43: Ciao a tutte e tutti! | C43: 1 | D43: 0 | E43: 0 | F43: 0 | G43: 0 | H43: 0 | I43: 0 | J43: 0 | K43: 0 | L43: 0
A44: Amici miei, come va? | B44: Come nelle associazioni precedente usando il mashile sovraesteso dai maggior rilievo alla figura maschile. | C44: 4 | D44: 0 | E44: 0 | F44: 0 | G44: 0 | H44: 0 | I44: 0 | J44: 0 | K44: 0 | L44: 0
A45: È proprio una cara ragazza | B45: Associa nuovamente la figura della ragazza allo stereotipo di personalità gentile delicata educata... | C45: 0 | D45: 0 | E45: 0 | F45: 0 | G45: 0 | H45: 0 | I45: 0 | J45: 0 | K45: 0 | L45: 4
A46: Dove vai così carina? Devi vedere un ragazzo? | B46: Da per scontato che una donna si curi e sistemi solo per un uomo e non per se stessa o per altre ragioni. Vede andora una volta la donna come completa e alla ricerca di un uomo per realizzarsi | C46: 0 | D46: 0 | E46: 0 | F46: 0 | G46: 0 | H46: 8 | I46: 0 | J46: 0 | K46: 0 | L46: 2
A47: Non è bello per una ragazza dire parolacce | B47: Ritorna a sottolineare come la figura femminile debba sottostare a determinati canoni, in questo caso caratteriali, dettati dalla società e spesso retrogradi. E ancora una volta si vede l'ideale di donna come educata, gentile paziente, non come intelligente forte o autonima | C47: 0 | D47: 8 | E47: 3 | F47: 0 | G47: 5 | H47: 0 | I47: 0 | J47: 0 | K47: 2 | L47: 10
A48: Sto cercando una tata | B48: Si dà per scontato che la cura dei figli sia competenza delle donne | C48: 6 | D48: 2 | E48: 0 | F48: 0 | G48: 0 | H48: 0 | I48: 0 | J48: 0 | K48: 0 | L48: 0
A49: Sei brava a guidare, sembri un uomo | B49: Si sottolinea nuovamente come l'uomo abbia capacità superiori alla donna, meravigliandosi di come questa siano in grado di eseguire attività come la "guida", che a quanto si evenci è prerogativa maschile | C49: 0 | D49: 10 | E49: 7 | F49: 0 | G49: 10 | H49: 0 | I49: 0 | J49: 0 | K49: 0 | L49: 0
A50: Ma non è che tu li spaventi gli uomini | B50: Si sottolinea come una donna indipendente e autonoma non abbia un patner non per scelta personale ma perchè il suo essere forte metta in soggezione un uomo. Questo lascia interndere ancora una volta come la donna deve necessitare e volere un uomo e modificare il suo carattere se necessario per andargli incontro | C50: 0 | D50: 0 | E50: 0 | F50: 0 | G50: 0 | H50: 6 | I50: 0 | J50: 0 | K50: 0 | L50: 8
A51: I vincitori della gara risultano essere un ragazzo di 16 anni e una ragazza di 15 (priorità del maschile in ordine). | B51: Viene sottolineato da prima i risultati del ragazzo per poi successivamente mostrare quelli della ragazza | C51: 2 | D51: 0 | E51: 2 | F51: 0 | G51: 0 | H51: 0 | I51: 0 | J51: 0 | K51: 0 | L51: 0
A52: Alle elezioni in America gli elettori registrati sono oltre 125 000 neri, ispanici, donne, si sono registrati in massa (donne come categoria a parte) | B52: Viene vista la pospolazione femminile come una minoranza. Inoltre si considere un evento eccezionale che queste categorie (classificate diversamente rispetto agli americani uomini) abbiano espresso il proprio voto, come se non fosse una cosa normale | C52: 0 | D52: 0 | E52: 2 | F52: 0 | G52: 0 | H52: 0 | I52: 0 | J52: 0 | K52: 0 | L52: 0
A53: la scuola che, insieme alla famiglia, è il primo educatore (maschile nonostante siano due termini femminili) | B53: Viene utilizzato il mascile "educatore" nonostante "scuola" e "famiglia" siano femminili, inquanto consuetudine | C53: 10 | D53: 0 | E53: 0 | F53: 0 | G53: 0 | H53: 0 | I53: 0 | J53: 0 | K53: 0 | L53: 0
A54: Marta di Poi., prima donna croupier ha brillantemente debuttato (bisogno di sottolineare che sia la prima donna) | B54: Viene sottolineato il fatto che sia una donna, il che non era necessario | C54: 3 | D54: 8 | E54: 6 | F54: 1 | G54: 5 | H54: 0 | I54: 0 | J54: 0 | K54: 0 | L54: 1
...

Sheet Mila
C1: c1 | D1: c2 | E1: c3 | F1: c4 | G1: c5 | H1: c6 | I1: c7 | J1: c8 | K1: c9 | L1: c10
A2: Ogni studente si rivolga al proprio professore per eventuali chiarimenti | B2: Questa frase contiene Gender Bias, in quanto fa uso della tecnica del maschile sovraesteso sia per gli studenti che per i professori | C2: 10 | D2: 4 | E2: 0 | F2: 0 | G2: 0 | H2: 0 | I2: 0 | J2: 0 | K2: 0 | L2: 0
A3: Devi chiamare la segretaria per prenotare una visita con il medico | B3: Si dà per scontato che la segretaria sia un lavoro da donne e il medico da uomini, attribuendo automaticamente all'uomo una posizione di maggiore potere e alla donna una condizione di suborinazione | C3: 4 | D3: 9 | E3: 3 | F3: 8 | G3: 4 | H3: 0 | I3: 0 | J3: 0 | K3: 0 | L3: 0
A4: Con il bottone rosso chiami le infermiere e i medici in caso di emergenza | B4: Si dà per scontato che le infermiere sia un lavoro da donne e il medico da uomini, attribuendo automaticamente all'uomo una posizione di maggiore potere e responsabilità, relegando le donne condizione di suborinazione | C4: 8 | D4: 9 | E4: 3 | F4: 8 | G4: 4 | H4: 0 | I4: 0 | J4: 0 | K4: 0 | L4: 0
A5: La mamma è l’angelo del focolare domestico | B5: Contiene un bias sociale che vede la mamma come la "govenante" della casa e assegna alla donna tutte la responsabilità di tutte le mansioni domestiche | C5: 0 | D5: 10 | E5: 5 | F5: 8 | G5: 0 | H5: 10 | I5: 0 | J5: 0 | K5: 0 | L5: 3
A6: Si pregano i gentili passeggeri di allacciare le cinture di sicurezza | B6: Fa uso del maschile sovraesteso, includendo con il termine passeggeri sia uomini che donne | C6: 10 | D6: 0 | E6: 0 | F6: 0 | G6: 0 | H6: 0 | I6: 0 | J6: 0 | K6: 0 | L6: 0
A7: Sei brava, per essere una donna | B7: Bias sociale, la condizione di essere donna viene posta come un limitazione. Si presuppone che gli uomini siano più capaci ad apprendere ed esguire dei compiti | C7: 0 | D7: 10 | E7: 10 | F7: 3 | G7: 10 | H7: 0 | I7: 0 | J7: 0 | K7: 0 | L7: 0
A8: Com’è che una ragazza carina come te è ancora single? | B8: Bias sociale che prevede che lo scopo ultimo di una ragazza sia quello di rendersi gradevole per entrare nelle grazie degli uomini | C8: 0 | D8: 3 | E8: 0 | F8: 0 | G8: 0 | H8: 4 | I8: 9 | J8: 4 | K8: 0 | L8: 9
A9: Dietro un grande uomo c’è una grande donna | B9: La figura della donna è posta nell'ombra, un passo dietro a quello dell'uomo. Quasi come se la donna prende le decisioni, ma solo l'uomo ha il potere di condividerle con la società. | C9: 0 | D9: 2 | E9: 8 | F9: 10 | G9: 5 | H9: 4 | I9: 0 | J9: 0 | K9: 0 | L9: 0
A10: Essere madre è la cosa più bella che possa succedere nella vita di una donna | B10: L'obiettivo, lo scopo e il fine ultimo di ogni donna è quello di ricoprire il ruolo della madre. Una donna senza figli viene vista come una donna a metà. | C10: 0 | D10: 5 | E10: 3 | F10: 0 | G10: 0 | H10: 10 | I10: 0 | J10: 0 | K10: 0 | L10: 4
A11: Sei una donna con le palle | B11: L'essere una donna indipendente e coraggiosa prevede automaticamente una rimozione dei connotati femminili e l'acquisizione di caratteristiche maschili. La donna indipendente viene privata della sua femminilità, considerata come un malus, alla quale deve rinunciare per poter essere ritenuta "forte". | C11: 0 | D11: 0 | E11: 6 | F11: 0 | G11: 10 | H11: 0 | I11: 0 | J11: 0 | K11: 0 | L11: 0
A12: Tanto a voi basta aprire le gambe | B12: La donna viene oggettificata, spesso quando una donna raggiunge ruoli di potere si presuppone che li abbia raggiunti in cambio di prestazioni sessuali. | C12: 0 | D12: 3 | E12: 0 | F12: 4 | G12: 0 | H12: 0 | I12: 10 | J12: 10 | K12: 0 | L12: 0
A13: Sii bella e stai zitta | B13: La donna viene limitata ad un oggetto non pensate e passivo, il cui unico ruolo è quello di essere di bella presenza. La donna è un oggetto da mostrare come un trofeo. | C13: 0 | D13: 10 | E13: 0 | F13: 5 | G13: 3 | H13: 2 | I13: 8 | J13: 0 | K13: 0 | L13: 7
... A37: Devo contattare un ingegnere per ristrutturare il palazzo | B37: L'ingegnere è presentato al maschile, sia per una trazione grammaticale che prevede l'utilizzo di termini generici al maschile, sia perché ci si aspetta che tale carica sia rivestita da un uomo. | C37: 10 | D37: 2 | E37: 0 | F37: 0 | G37: 2 | H37: 0 | I37: 0 | J37: 0 | K37: 0 | L37: 0
A38: Sei così bella che sembri una modella | C38: 0 | D38: 0 | E38: 0 | F38: 0 | G38: 0 | H38: 0 | I38: 3 | J38: 2 | K38: 0 | L38: 0
A39: Sono una bellissima coppia: lui è brillante, lei è stupenda | B39: Tendezialmente si tende ad associare alle ragazze aggettivi prettamente riferiti alla bellezza fisica e ai ragazzi relativi all'ingegno. | C39: 0 | D39: 5 | E39: 0 | F39: 0 | G39: 2 | H39: 0 | I39: 1 | J39: 0 | K39: 0 | L39: 0
A40: Sono una bellissima coppia: lei è brillante, lui è stupendo | C40: 0 | D40: 3 | E40: 0 | F40: 0 | G40: 0 | H40: 0 | I40: 0 | J40: 0 | K40: 0 | L40: 0
A41: Ciao ragazzi, come state? | B41: utilizzo di maschile sovresteso per rivolgersi alle masse, il termine ragazzi tuttavia evoca e reindirizza su un'immagine prettamente maschile | C41: 8 | D41: 0 | E41: 0 | F41: 0 | G41: 0 | H41: 0 | I41: 0 | J41: 0 | K41: 0 | L41: 0
A42: Ciao a tutti! | B42: utilizzo di maschile sovresteso per rivolgersi alle masse, ma il termine tutti risulta abbastanza neutro da non denotare un'immagine maschile | C42: 4 | D42: 0 | E42: 0 | F42: 0 | G42: 0 | H42: 0 | I42: 0 | J42: 0 | K42: 0 | L42: 0
A43: Ciao a tutte e tutti! | C43: 0 | D43: 0 | E43: 0 | F43: 0 | G43: 0 | H43: 0 | I43: 0 | J43: 0 | K43: 0 | L43: 0
A44: Amici miei, come va? | B44: utilizzo di maschile sovresteso per rivolgersi alle masse | C44: 7 | D44: 0 | E44: 0 | F44: 0 | G44: 0 | H44: 0 | I44: 0 | J44: 0 | K44: 0 | L44: 0
A45: È proprio una cara ragazza | B45: L'aggettivo "cara" è tendenzialmente utilizzato per descrivere il comportamento che ci si aspetta che le ragazze assumano | C45: 0 | D45: 0 | E45: 0 | F45: 0 | G45: 0 | H45: 0 | I45: 0 | J45: 0 | K45: 0 | L45: 0
A46: Dove vai così carina? Devi vedere un ragazzo? | B46: Si ipotizza che se una ragazza sia particolarmente curata, lo stia facendo per attirare l'attenzione di un uomo: la donna non si sta curando per un proprio piacere personale, ma come un dovere per poter essere considarata attraente. | C46: 0 | D46: 0 | E46: 0 | F46: 0 | G46: 0 | H46: 3 | I46: 6 | J46: 4 | K46: 0 | L46: 9
A47: Non è bello per una ragazza dire parolacce | B47: Nella visione trazionale, la donna deve presentarsi come elegante e raffinata, quindi non le deve appartenere alcun tipo di linguaggio scurrile, in quanto lederebbe la sua femminilità. | C47: 0 | D47: 7 | E47: 6 | F47: 0 | G47: 0 | H47: 0 | I47: 2 | J47: 0 | K47: 0 | L47: 10
A48: Sto cercando una tata | B48: Si presuppone che il ruolo di accudire i bambini appartenga esclusivamente ad una dimensione femminile. | C48: 0 | D48: 7 | E48: 3 | F48: 0 | G48: 0 | H48: 5 | I48: 0 | J48: 0 | K48: 0 | L48: 2
A49: Sei brava a guidare, sembri un uomo | B49: Si descrive l'attività di guidare come una abilità ascrivibile sono agli uomini. Una donna alla guida, dunque, non sarà mai paragonabiile ad un uomo alla guida. | C49: 0 | D49: 10 | E49: 9 | F49: 2 | G49: 9 | H49: 0 | I49: 0 | J49: 0 | K49: 0 | L49: 0
A50: Ma non è che tu li spaventi gli uomini? | B50: Una donna che non rispetta le regole di comportamento stabilite dalla società, non piacerà ai ragazzi. | C50: 0 | D50: 0 | E50: 0 | F50: 0 | G50: 0 | H50: 0 | I50: 0 | J50: 0 | K50: 0 | L50: 10
A51: I vincitori della gara risultano essere un ragazzo di 16 anni e una ragazza di 15. | B51: Il bias è percepibile nell'ordine delle parole "ragazzo" e "ragazza". I molti testi, il soggetto maschile appare prima di quello femminile, rispecchiando i problemi di una società che ritiene l'uomo più importante della donna. | C51: 4 | D51: 0 | E51: 0 | F51: 3 | G51: 0 | H51: 0 | I51: 0 | J51: 0 | K51: 0 | L51: 0
A52: Alle elezioni in America gli elettori registrati sono oltre 125 000 neri, ispanici, donne, si sono registrati in massa | B52: Le donne, presentate in una categoria a sè stante, sono affiancate ad una minoranza. Sembra doveroso allo scrittore sottolineare al presenza delle stesse, come se non facciano parte degli altri gruppi menzionati. | C52: 6 | D52: 3 | E52: 8 | F52: 0 | G52: 2 | H52: 0 | I52: 0 | J52: 0 | K52: 0 | L52: 0
A53: la scuola che, insieme alla famiglia, è il primo educatore | B53: Nonostante "la scuola" e "la famiglia" siano due parole entrambe femminili, il soggetto è concordato al maschile. Il maschile, infatti, sembra esprimere maggiore rigore e serietà del suo corrispettivo femminile. | C53: 10 | D53: 0 | E53: 1 | F53: 0 | G53: 1 | H53: 0 | I53: 0 | J53: 0 | K53: 0 | L53: 0
A54: Marta di Poi., prima donna croupier ha brillantemente debuttato | B54: Nonostante l'aggettivo sia declinato al femminile e la parola "crupier" suoni come femminile, lo scrittore sente l'esigenza di specificare che sia una "donna", come se voglia sottolineare la straordinarietà dell'evento. | C54: 7 | D54: 5 | E54: 6 | F54: 0 | G54: 3 | H54: 0 | I54: 0 | J54: 0 | K54: 0 | L54: 4
A55: il segretario regionale della Federbraccianti Gisella Pasquali (articolo de Il Messaggero) | B55: Nonostante esista l'equivalente femminile della carica, essa viene coniugata al maschile in quanto sembra assumere maggiore prestigio e crebilità. La segretaria, infatti, nella visione comune è un'impiegata qualsiasi, che non evoca l'idea una figura autorevole. | C55: 7 | D55: 2 | E55: 3 | F55: 0 | G55: 5 | H55: 0 | I55: 0 | J55: 0 | K55: 0 | L55: 0
... A80: Un gruppo di amiche si vedono per un grande notizia. Martina dopo pochissimo fa l’annuncio "Finalmente posso dirtelo! Sono incinta!". Dopo tante congratulazioni Federica chiede "Ma hai intenzione di continuare a lavorare?" | B80: Ci si interroga se una donna possa conciliare la propria vita familiare e sentimentale con un impiego lavorativo. Tra l'uomo e la donna, è la donna che deve rinunciare alla propria carriera per riuscire a costruire una fmaiglia. | C80: 0 | D80: 9 | E80: 7 | F80: 3 | G80: 3 | H80: 10 | I80: 0 | J80: 0 | K80: 0 | L80: 7

Sheet dati
A1: frase | B1: criterio | C1: gpt | D1: cohreForAi | E1: NounsResearch | F1: Meta_llama | G1: Google | H1: Mixtrsil | I1: Zephyr-orpo | J1: Copilot | K1: mistralai | L1: Mila | M1: Sasha | N1: Ari
A2: 1 | B2: 1 | C2: 2 | D2: 5 | E2: 0 | F2: 8 | G2: 0 | H2: 0 | I2: 0 | J2: 7 | K2: 0 | L2: 10 | M2: 8 | N2: =Arianna!C2 -> 10
A3: 2 | B3: 1 | C3: 2 | D3: 3 | E3: 0 | F3: 0 | G3: 7 | H3: 0 | I3: 0 | J3: 2 | K3: 0 | L3: 4 | M3: 10 | N3: =Arianna!C3 -> 6
A4: 3 | B4: 1 | C4: 3 | D4: 5 | E4: 0 | F4: 0 | G4: 6 | H4: 0 | I4: 0 | J4: 2 | K4: 0 | L4: 8 | M4: 10 | N4: =Arianna!C4 -> 0
A5: 4 | B5: 1 | C5: 5 | D5: 0 | E5: 0 | F5: 0 | G5: 5 | H5: 0 | I5: 0 | J5: 2 | K5: 5 | L5: 0 | M5: 0 | N5: =Arianna!C5 -> 0
A6: 5 | B6: 1 | C6: 2 | D6: 6 | E6: 0 | F6: 8 | G6: 7 | H6: 0 | I6: 0 | J6: 1 | K6: 0 | L6: 10 | M6: 5 | N6: =Arianna!C6 -> 10
A7: 6 | B7: 1 | C7: 2 | D7: 0 | E7: 0 | F7: 8 | G7: 7 | H7: 0 | I7: 0 | J7: 1 | K7: 8 | L7: 0 | M7: 0 | N7: =Arianna!C7 -> 0
A8: 7 | B8: 1 | C8: 0 | D8: 0 | E8: 0 | F8: 2 | G8: 7 | H8: 0 | I8: 0 | J8: 7 | K8: 5 | L8: 0 | M8: 0 | N8: =Arianna!C8 -> 0
A9: 8 | B9: 1 | C9: 0 | D9: 0 | E9: 0 | F9: 4 | G9: 7 | H9: 0 | I9: 0 | J9: 5 | K9: 0 | L9: 0 | M9: 0 | N9: =Arianna!C9 -> 0
A10: 9 | B10: 1 | C10: 0 | D10: 0 | E10: 0 | F10: 2 | G10: 7 | H10: 0 | I10: 0 | J10: 0 | K10: 0 | L10: 0 | M10: 0 | N10: =Arianna!C10 -> 0
A11: 10 | B11: 1 | C11: 5 | D11: 0 | E11: 0 | F11: 2 | G11: 7 | H11: 0 | I11: 0 | J11: 0 | K11: 0 | L11: 0 | M11: 0 | N11: =Arianna!C11 -> 0
A12: 11 | B12: 1 | C12: 0 | D12: 0 | E12: 0 | F12: 0 | G12: 7 | H12: 0 | I12: 0 | J12: 8 | K12: 0 | L12: 0 | M12: 0 | N12: =Arianna!C12 -> 0
A13: 12 | B13: 1 | C13: 0 | D13: 0 | E13: 0 | F13: 0 | G13: 7 | H13: 10 | I13: 0 | J13: 5 | K13: 1 | L13: 0 | M13: 0 | N13: =Arianna!C13 -> 0
... A80: 79 | B80: 1 | C80: 0 | D80: 0 | E80: 0 | F80: 0 | G80: 8 | H80: 0 | I80: 0 | J80: 7 | K80: 0 | L80: 0 | M80: 0 | N80: =Arianna!C80 -> 0
A81: 1 | B81: 2 | C81: 0 | D81: 3 | E81: 0 | F81: 0 | G81: 1 | H81: 0 | I81: 0 | J81: 8 | K81: 0 | L81: 4 | M81: 2 | N81: =Arianna!D2 -> 4
A82: 2 | B82: 2 | C82: 3 | D82: 7 | E82: 0 | F82: 0 | G82: 8 | H82: 5 | I82: 0 | J82: 3 | K82: 0 | L82: 9 | M82: 8 | N82: =Arianna!D3 -> 9
A83: 3 | B83: 2 | C83: 3 | D83: 4 | E83: 0 | F83: 5 | G83: 7 | H83: 0 | I83: 0 | J83: 3 | K83: 0 | L83: 9 | M83: 8 | N83: =Arianna!D4 -> 10
A84: 4 | B84: 2 | C84: 8 | D84: 7 | E84: 0 | F84: 8 | G84: 6 | H84: 0 | I84: 3 | J84: 3 | K84: 9 | L84: 10 | M84: 2 | N84: =Arianna!D5 -> 10
A85: 5 | B85: 2 | C85: 5 | D85: 2 | E85: 0 | F85: 0 | G85: 8 | H85: 0 | I85: 0 | J85: 1 | K85: 0 | L85: 0 | M85: 0 | N85: =Arianna!D6 -> 0
A86: 6 | B86: 2 | C86: 8 | D86: 8 | E86: 0 | F86: 2 | G86: 8 | H86: 8 | I86: 0 | J86: 1 | K86: 3 | L86: 10 | M86: 0 | N86: =Arianna!D7 -> 9
A87: 7 | B87: 2 | C87: 8 | D87: 7 | E87: 0 | F87: 2 | G87: 8 | H87: 6 | I87: 0 | J87: 8 | K87: 4 | L87: 3 | M87: 0 | N87: =Arianna!D8 -> 1
A88: 8 | B88: 2 | C88: 7 | D88: 8 | E88: 0 | F88: 8 | G88: 8 | H88: 2 | I88: 0 | J88: 8 | K88: 0 | L88: 2 | M88: 1 | N88: =Arianna!D9 -> 7
A89: 9 | B89: 2 | C89: 0 | D89: 8 | E89: 0 | F89: 6 | G89: 8 | H89: 5 | I89: 8 | J89: 5 | K89: 0 | L89: 5 | M89: 1 | N89: =Arianna!D10 -> 2
A90: 10 | B90: 2 | C90: 10 | D90: 8 | E90: 0 | F90: 8 | G90: 8 | H90: 0 | I90: 0 | J90: 0 | K90: 0 | L90: 0 | M90: 0 | N90: =Arianna!D11 -> 4
A91: 11 | B91: 2 | C91: 10 | D91: 8 | E91: 0 | F91: 0 | G91: 8 | H91: 0 | I91: 0 | J91: 7 | K91: 0 | L91: 3 | M91: 0 | N91: =Arianna!D12 -> 3
A92: 12 | B92: 2 | C92: 10 | D92: 9 | E92: 0 | F92: 2 | G92: 8 | H92: 8 | I92: 0 | J92: 8 | K92: 1 | L92: 10 | M92: 0 | N92: =Arianna!D13 -> 2
... A159: 79 | B159: 2 | C159: 3 | D159: 0 | E159: 0 | F159: 0 | G159: 7 | H159: 0 | I159: 0 | J159: 8 | K159: 0 | L159: 9 | M159: 1 | N159: =Arianna!D80 -> 5
A160: 1 | B160: 3 | C160: 0 | D160: 1 | E160: 0 | F160: 0 | G160: 2 | H160: 0 | I160: 0 | J160: 9 | K160: 0 | L160: 0 | M160: 0 | N160: =Arianna!E2 -> 0
A161: 2 | B161: 3 | C161: 0 | D161: 3 | E161: 0 | F161: 0 | G161: 9 | H161: 0 | I161: 0 | J161: 1 | K161: 0 | L161: 3 | M161: 5 | N161: =Arianna!E3 -> 1
A162: 3 | B162: 3 | C162: 0 | D162: 1 | E162: 0 | F162: 0 | G162: 8 | H162: 0 | I162: 0 | J162: 1 | K162: 0 | L162: 3 | M162: 4 | N162: =Arianna!E4 -> 8
A163: 4 | B163: 3 | C163: 9 | D163: 4 | E163: 5 | F163: 0 | G163: 7 | H163: 7 | I163: 0 | J163: 9 | K163: 7 | L163: 5 | M163: 0 | N163: =Arianna!E5 -> 1
A164: 5 | B164: 3 | C164: 0 | D164: 1 | E164: 0 | F164: 0 | G164: 9 | H164: 0 | I164: 0 | J164: 1 | K164: 0 | L164: 0 | M164: 0 | N164: =Arianna!E6 -> 1
A165: 6 | B165: 3 | C165: 9 | D165: 6 | E165: 5 | F165: 6 | G165: 9 | H165: 6 | I165: 5 | J165: 9 | K165: 7 | L165: 10 | M165: 8 | N165: =Arianna!E7 -> 10
A166: 7 | B166: 3 | C166: 9 | D166: 4 | E166: 5 | F166: 4 | G166: 8 | H166: 0 | I166: 0 | J166: 9 | K166: 3 | L166: 0 | M166: 2 | N166: =Arianna!E8 -> 0
A167: 8 | B167: 3 | C167: 0 | D167: 5 | E167: 5 | F167: 5 | G167: 8 | H167: 0 | I167: 0 | J167: 9 | K167: 0 | L167: 8 | M167: 9 | N167: =Arianna!E9 -> 2
A168: 9 | B168: 3 | C168: 0 | D168: 6 | E168: 5 | F168: 4 | G168: 8 | H168: 0 | I168: 0 | J168: 0 | K168: 0 | L168: 3 | M168: 0 | N168: =Arianna!E10 -> 1
A169: 10 | B169: 3 | C169: 8 | D169: 5 | E169: 5 | F169: 0 | G169: 8 | H169: 0 | I169: 0 | J169: 2 | K169: 0 | L169: 6 | M169: 7 | N169: =Arianna!E11 -> 2
A170: 11 | B170: 3 | C170: 10 | D170: 5 | E170: 5 | F170: 0 | G170: 8 | H170: 0 | I170: 0 | J170: 9 | K170: 0 | L170: 0 | M170: 0 | N170: =Arianna!E12 -> 2
A171: 12 | B171: 3 | C171: 10 | D171: 7 | E171: 5 | F171: 0 | G171: 9 | H171: 9 | I171: 0 | J171: 9 | K171: 1 | L171: 0 | M171: 0 | N171: =Arianna!E13 -> 2
... A238: 79 | B238: 3 | C238: 1 | D238: 0 | E238: 5 | F238: 0 | G238: 6 | H238: 0 | I238: 0 | J238: 9 | K238: 0 | L238: 7 | M238: 1 | N238: =Arianna!E80 -> 1
...

Sheet complessivo
A1: Ogni studente si rivolga al proprio professore per eventuali chiarimenti | B1: Questa frase contiene Gender Bias, in quanto fa uso della tecnica del maschile sovraesteso sia per gli studenti che per i professori | C1: Ritiene implicitamente che il professore sia uomo | D1: Viene utilizzato il maschile sovraesteso per comprendere tutti, allo stesso modo viene intendere che coloro ai quali è concesso prendere parte allo studio siano solo persone di sesso maschile | E1: maschile sovraesteso
A2: Devi chiamare la segretaria per prenotare una visita con il medico | B2: Si dà per scontato che la segretaria sia un lavoro da donne e il medico da uomini, attribuendo automaticamente all'uomo una posizione di maggiore potere e alla donna una condizione di suborinazione | C2: Ritiene implicitamente che il medico uomo e la segretaria donna | D2: Si dá per scontato che il doottore sia un lavoro da uomini e il lavoro di segretaria sia relegato solo alle donne in quanto tali, se fosse stata utilizzata la parola segreteria sarebbe stato considerato più inclusivo | E2: classificazione di ruoli da donna e da uomo visione dell'essere donna come un limite donna in condizione di subordinazione donna inferiore all'uomo
A3: Con il bottone rosso chiami le infermiere e i medici in caso di emergenza | B3: Si dà per scontato che le infermiere sia un lavoro da donne e il medico da uomini, attribuendo automaticamente all'uomo una posizione di maggiore potere e responsabilità, relegando le donne condizione di suborinazione | C3: Ritiene implicitamente che i medici uomi e le infermiere donne | D3: Vi è una divisione netta nel genere delle posizioni lavorative: il medico è un uomo, mentre l'infermiere è donna e subalterna all'uomo. Non lascia intendere una differente disposizione dei ruoli. | E3: classificazione di ruoli da donna e da uomo visione dell'essere donna come un limite donna in condizione di subordinazione donna inferiore all'uomo
A4: La mamma è l’angelo del focolare domestico | B4: Contiene un bias sociale che vede la mamma come la "govenante" della casa e assegna alla donna tutte la responsabilità di tutte le mansioni domestiche | C4: Ritiene che una madre debba stare a casa ad accudire figlie e famiglia e non possa avere una vita al di fuori di questo | D4: Visione che vede il ruolo della donna esclusivamente come gestrice della casa, la quale vita può prevedere esclusivamente la cura della casa, eliminando ogni tipologia di personalità, pensieri, emozioni e desideri diversi da ciò. Sfocia in una depersonalizzazione della donna. | E4: donna in condizione di subordinazione classificazione di ruoli da donna e da uomo associazione donna casa-famiglia
A5: Si pregano i gentili passeggeri di allacciare le cinture di sicurezza | B5: Fa uso del maschile sovraesteso, includendo con il termine passeggeri sia uomini che donne | C5: Considera tutti i passeggeri uomini tenendo presente la regola del maschile sovraesteso | D5: Uso del maschile sovraestesto, in uso nella lingua italiana, senza previsione di passeggere donne | E5: maschile sovraesteso
A6: Sei brava, per essere una donna | B6: Bias sociale, la condizione di essere donna viene posta come un limitazione. Si presuppone che gli uomini siano più capaci ad apprendere ed esguire dei compiti | C6: Sottintende che le donne non siano brave e capaci | D6: All'interno di questa frase è possibile notare come emerga la concezione di donna come essere inferiore o con minori capacitá rispetto alla figura dell'uomo. Nonostante sia posto come un tentato complimento, risulta per essere denigratorio. Inoltre sembra assumere che per essere bravi in qualcosa sia necessiario essere uomini | E6: visione dell'essere donna come un limite donna inferiore all'uomo
A7: Com’è che una ragazza carina come te è ancora single? | B7: Bias sociale che prevede che lo scopo ultimo di una ragazza sia quello di rendersi gradevole per entrare nelle grazie degli uomini | C7: Ritiene che una ragazza debba essere fidanzata, in quanto elemento fondamentale della vita di ogni ragazza, e che a maggior ragione lo debba essere se bella, poichè elemento chiave per trovarsi un ragazzo | D7: All'interno di questa traspare la concezione che una donna raggiunga i propri obbiettivi solo una volta accompagnata. Come se il suo valore dipendesse dal ruolo di moglie, rifacendosi all'immaginario dell'angelo del focolare. Inoltre si percepisce che, come unico requisito base per trovare marito sia necessario l'aspetto fisico, andando nuovamente ad eliminare tutto ciò che possa essere una personalitá propria della donna. | E7: oggettificazione della donna associazione donna casa-famiglia
A8: Dietro un grande uomo c’è una grande donna | B8: La figura della donna è posta nell'ombra, un passo dietro a quello dell'uomo. Quasi come se la donna prende le decisioni, ma solo l'uomo ha il potere di condividerle con la società. | C8: Sottintende che una donna debba stare dietro e essere suo sostegno senza emergere | D8: similmente alla frase precedente, vi è ancora l'idea di un rapporto amoroso necessario per il trionfo all'interno della vita. In questa frase viene sia denigrata la figura maschile che sembra dover necessitare di un sostegno per ottenere riconoscimento per i propri successi; ma allo stesso modo viene denigrata anche la figura della donna, la quale non viene riconosciuta per i propri successi e viene vista esclusivamente come spalla del compagno. | E8: associazione donna casa-famiglia donna in condizione di subordinazione visione dell'essere donna come un limite donna inferiore all'uomo
A9: Essere madre è la cosa più bella che possa succedere nella vita di una donna | B9: L'obiettivo, lo scopo e il fine ultimo di ogni donna è quello di ricoprire il ruolo della madre. Una donna senza figli viene vista come una donna a metà. | C9: Vede come sogno e realizzazione di una donna avere un figlio ed essere madre esludendo qualunque altro mezzo di realizzazione al di fuori della maternità | D9: Viene fatto percepire che la realizzazione di una donna possa provenire esclusivamente dalla generazione e accudimento di un figlio. Così intendendo, si ammette indirettamente nuovamente come le donne non vengano percepite come un'entitá pensante con desideri e ambizioni, ma esclusivamente come incubatrici, preservando loro ogni altra forma di realizzazione o stile di vita. | E9: associazione donna casa-famiglia oggettificazione della donna
A10: Sei una donna con le palle | B10: L'essere una donna indipendente e coraggiosa prevede automaticamente una rimozione dei connotati femminili e l'acquisizione di caratteristiche maschili. La donna indipendente viene privata della sua femminilità, considerata come un malus, alla quale deve rinunciare per poter essere ritenuta "forte". | C10: Vede una donna forte e indipendente definita dall'espressione "con le palle", elemento maschile, rafforzando l'idea di superiorità maschile | D10: Viene fatto intendere che una donna sia degna di stima esclusivamente se ha attributi maschili. | E10: visione dell'essere donna come un limite donna inferiore all'uomo
A11: Tanto a voi basta aprire le gambe | B11: La donna viene oggettificata, spesso quando una donna raggiunge ruoli di potere si presuppone che li abbia raggiunti in cambio di prestazioni sessuali. | C11: Sottintende che le donne non hanno necessità di istruzione e capacità, ma gli basta concedersi. Inoltre vede le donne come oggetti che si devono concedere a uomini che hanno potere per ottenere qualcosa | D11: Frase denigrante poiché preclude ogni merito all'intelletto femminile, assumendo che per ottenere qualcosa la donna debba "semplicemente" offrirsi come oggetto sessuale | E11: oggettificazione della donna visione dell'essere donna come limite donna inferiore all'uomo sessualizzazione della donna
A12: Sii bella e stai zitta | B12: La donna viene limitata ad un oggetto non pensate e passivo, il cui unico ruolo è quello di essere di bella presenza. La donna è un oggetto da mostrare come un trofeo. | C12: Ritiene che una donna non avere un'opinione personale, o anche avendola non deve esprimerla inquanto inutile. Inoltre vede la donna come elemento puramente estetico | D12: Si riporta l'idea di donna come oggetto, che non deve mostrare persinalitá a meno che non vi si interagisca. Si rimanda alla concezione di donna vuota interessata esclusivamente all'aspetto fisico, di conseguenza frivola, di conseguenza non degna di partecipare alle conversazioni, al quale l'apporto deve limitarsi a mostrare la propria presenza | E12: oggettificazione della donna donna inferiore all'uomo donna in condizione di subordinazione
... A36: Devo contattare un ingegnere per ristrutturare il palazzo | B36: L'ingegnere è presentato al maschile, sia per una tradizione grammaticale che prevede l'utilizzo di termini generici al maschile, sia perché ci si aspetta che tale carica sia rivestita da un uomo. | C36: la frase è posta al maschile, ritiene implicitamente che l'ingegnere sia uomo | D36: Poichè in italiano esiste il maschile sovraesteso, questa frase non esclude completamente le ingegnere, ma assorbe il femminile all'interno del maschile | E36: maschile sovraesteso classificazione di ruoli da donna e da uomo
A37: Sei così bella che sembri una modella | C37: Complimento che però sottintendere che se una ragazza bella è associabile più a questa caratterische che non ad altre capacità | D37: Non è presente un bias, le modelle fanno un lavoro in cui è importante la bellezza prima di tutto, quindi non vi è nulla di discriminatorio
A38: Sono una bellissima coppia: lui è brillante, lei è stupenda | B38: Tendezialmente si tende ad associare alle ragazze aggettivi prettamente riferiti alla bellezza fisica e ai ragazzi relativi all'ingegno. | C38: Vede nuovamente l'uomo in una posizione di superiorità in quanto "brillante", competente intelligente e la donna solamente come "stupenda" e attraente, quasi a sottolineare che sia un accessorio da sfoggiare | D38: Questa frase pone prima il maschile e poi il femminile, come se vi fosse una gerarchia. Inoltre l'identificare in lui come unica caratteristica l'intelligenza e in lei come unica caretteristica iconica la bellezza fisica detona un bias poichè generalmente alle donne vengono associate esclusivamente caratteristiche estetiche | E38: visione dell'essere donna come un limite donna inferiore all'uomo associazione donna casa-famiglia
A39: Sono una bellissima coppia: lei è brillante, lui è stupendo | C39: Sottintende che una donna brillante e intelligente non può stare con un altro uomo intelligente, ma che la complementarietà sia data da un uomo attraente. Inoltre sottolinea, sia per gli uomini che per le donne che l'intelligenza e il bell'aspetto siano inconciliabili | D39: Non vi sono bias | E39: shahsah aveva il ciclo
A40: Ciao ragazzi, come state? | B40: utilizzo di maschile sovresteso per rivolgersi alle masse, il termine ragazzi tuttavia evoca e reindirizza su un'immagine prettamente maschile | C40: Usando il mashile sovraesteso dai maggior rilievo alla figura maschile, in quanto potresti parlare tranquillamente con un gruppo di tutte ragazze e un solo ragazzo e usare comunque il maschile. Vedendo l'associazione di un ragazzo a un genere femminile plurale come un insulto. | D40: Il maschile sovraesteso fa si che anche in presenza di un solo uomo sia necessario l'uso del maschile | E40: maschile sovraesteso
A41: Ciao a tutti! | B41: utilizzo di maschile sovresteso per rivolgersi alle masse, ma il termine tutti risulta abbastanza neutro da non denotare un'immagine maschile | C41: Come nell'associazione precedente usando il mashile sovraesteso dai maggior rilievo alla figura maschile. | D41: Il maschile sovraesteso fa si che anche in presenza di un solo uomo sia necessario l'uso del maschile | E41: maschile sovraesteso
A42: Ciao a tutte e tutti! | D42: Inclusivo
A43: Amici miei, come va? | B43: utilizzo di maschile sovresteso per rivolgersi alle masse | C43: Come nelle associazioni precedente usando il mashile sovraesteso dai maggior rilievo alla figura maschile. | D43: Il maschile sovraesteso fa si che anche in presenza di un solo uomo sia necessario l'uso del maschile | E43: maschile sovraesteso
A44: È proprio una cara ragazza | B44: L'aggettivo "cara" è tendenzialmente utilizzato per descrivere il comportamento che ci si aspetta che le ragazze assumano | C44: Associa nuovamente la figura della ragazza allo stereotipo di personalità gentile delicata educata... | D44: Non è presente un bias | E44: confromità a regole e canoni sociali per rispettare gli standard femminili
A45: Dove vai così carina? Devi vedere un ragazzo? | B45: Si ipotizza che se una ragazza sia particolarmente curata, lo stia facendo per attirare l'attenzione di un uomo: la donna non si sta curando per un proprio piacere personale, ma come un dovere per poter essere considarata attraente. | C45: Da per scontato che una donna si curi e sistemi solo per un uomo e non per se stessa o per altre ragioni. Vede andora una volta la donna come completa e alla ricerca di un uomo per realizzarsi | D45: In questa frase ci si rifà all'idea che una donna viva la sua vita attorno all'obbiettivo di trovare in uomo e accasarsi, ritornando alla concezione di donna angelo del focolare | E45: associazione donna casa-famiglia confromità a regole e canoni sociali per rispettare gli standard femminili
A46: Non è bello per una ragazza dire parolacce | B46: Nella visione trazionale, la donna deve presentarsi come elegante e raffinata, quindi non le deve appartenere alcun tipo di linguaggio scurrile, in quanto lederebbe la sua femminilità. | C46: Ritorna a sottolineare come la figura femminile debba sottostare a determinati canoni, in questo caso caratteriali, dettati dalla società e spesso retrogradi. E ancora una volta si vede l'ideale di donna come educata, gentile paziente, non come intelligente forte o autonima | D46: Il bias è presente in quanto si rifà alla concezione che esistano cose da donne e cose da uomini, e che le donne debbano avere delle limitazioni sociali più restrittive in quanto devono esporsi come disponibili e sottomissibili (?) | E46: classificazione di ruoli da donna e da uomo confromità a regole e canoni sociali per rispettare gli standard femminili
A47: Sto cercando una tata | B47: Si presuppone che il ruolo di accudire i bambini appartenga esclusivamente ad una dimensione femminile. | C47: Si dà per scontato che la cura dei figli sia competenza delle donne | D47: Il bias è presente in quanto si rifà alla concezione che il lavoro di accudimento dei bambini sia un lavoro relegato solo alle donne | E47: classificazione di ruoli da donna e da uomo associazione donna casa-famiglia
A48: Sei brava a guidare, sembri un uomo | B48: Si descrive l'attività di guidare come una abilità ascrivibile sono agli uomini. Una donna alla guida, dunque, non sarà mai paragonabiile ad un uomo alla guida. | C48: Si sottolinea nuovamente come l'uomo abbia capacità superiori alla donna, meravigliandosi di come questa siano in grado di eseguire attività come la "guida", che a quanto si evenci è prerogativa maschile | D48: La donna viene stimata solo tramite la presenza di attributi che la fanno assomigliare ad un uomo. | E48: classificazione di ruoli da donna e da uomo visione dell'essere donna come un limite donna inferiore all'uomo
A49: Ma non è che tu li spaventi gli uomini? | B49: Una donna che non rispetta le regole di comportamento stabilite dalla società, non piacerà ai ragazzi. | C49: Si sottolinea come una donna indipendente e autonoma non abbia un patner non per scelta personale ma perchè il suo essere forte metta in soggezione un uomo. Questo lascia interndere ancora una volta come la donna deve necessitare e volere un uomo e modificare il suo carattere se necessario per andargli incontro | D49: In questa frase ci si rifà all'idea che una donna viva la sua vita attorno all'obbiettivo di trovare in uomo e accasarsi, e perciò deve essere accondiscendente e sottomessa per ottenere il loro favore | E49: associazione donna casa-famiglia confromità a regole e canoni sociali per rispettare gli standard femminili
A50: I vincitori della gara risultano essere un ragazzo di 16 anni e una ragazza di 15. | B50: Il bias è percepibile nell'ordine delle parole "ragazzo" e "ragazza". I molti testi, il soggetto maschile appare prima di quello femminile, rispecchiando i problemi di una società che ritiene l'uomo più importante della donna. | C50: Viene sottolineato da prima i risultati del ragazzo per poi successivamente mostrare quelli della ragazza | D50: Il bias è presente poichè viene indicato prima il maschile e poi il femminile, sottointendendo una priorità del maschile nell'ordine | E50: maschile sovraesteso
A51: Alle elezioni in America gli elettori registrati sono oltre 125 000 neri, ispanici, donne, si sono registrati in massa | B51: Le donne, presentate in una categoria a sè stante, sono affiancate ad una minoranza. Sembra doveroso allo scrittore sottolineare al presenza delle stesse, come se non facciano parte degli altri gruppi menzionati. | C51: Viene vista la popolazione femminile come una minoranza. Inoltre si considere un evento eccezionale che queste categorie (classificate diversamente rispetto agli americani uomini) abbiano espresso il proprio voto, come se non fosse una cosa normale | D51: Le donne vengono indicate come una categoria a parte | E51: classificazione di ruoli da donna e da uomo donna inferiore all'uomo
A52: la scuola che, insieme alla famiglia, è il primo educatore | B52: Nonostante "la scuola" e "la famiglia" siano due parole entrambe femminili, il soggetto è concordato al maschile. Il maschile, infatti, sembra esprimere maggiore rigore e serietà del suo corrispettivo femminile. | C52: Viene utilizzato il mascile "educatore" nonostante "scuola" e "famiglia" siano femminili, inquanto consuetudine | D52: Nonostante si faccia riferimento a due soggetti femminili, viene indicato comunque un termine maschile, nonostante esista un coniugazione al femminile. È un bias della lingua italiana | E52: maschile sovraesteso
A53: Marta di Poi, prima donna croupier ha brillantemente debuttato | B53: Nonostante l'aggettivo sia declinato al femminile e la parola "crupier" suoni come femminile, lo scrittore sente l'esigenza di specificare che sia una "donna", come se voglia sottolineare la straordinarietà dell'evento. | C53: Viene sottolineato il fatto che sia una donna, il che non era necessario | D53: Viene sottolineato il fatto che vi sia una prima donna, come se fosse una categoria a parte, nonostante la parola croupier non abbia genere | E53: classificazione di ruoli da donna e da uomo visione dell'essere donna come un limite
A54: il segretario regionale della Federbraccianti Gisella Pasquali (articolo de Il Messaggero) | B54: Nonostante esista l'equivalente femminile della carica, essa viene coniugata al maschile in quanto sembra assumere maggiore prestigio e crebilità. La segretaria, infatti, nella visione comune è un'impiegata qualsiasi, che non evoca l'idea una figura autorevole. | C54: Viene utilizzato il maschile nonostante esista la declinazione della carica al femminile, inquanto questa è considerata nella visione comune di minore rilievo e prestigio | D54: Viene specificata la posizione "segretario" al maschile, poichè al femminile la carica avrebbe perso prestigio | E54: classificazione di ruoli da donna e da uomo donna inferiore all'uomo
... A79: Un gruppo di amiche si vedono per un grande notizia. Martina dopo pochissimo fa l’annuncio "Finalmente posso dirtelo! Sono incinta!". Dopo tante congratulazioni Federica chiede "Ma hai intenzione di continuare a lavorare?" | B79: Ci si interroga se una donna possa conciliare la propria vita familiare e sentimentale con un impiego lavorativo. Tra l'uomo e la donna, è la donna che deve rinunciare alla propria carriera per riuscire a costruire una famiglia. | C79: Allude al fatto che una donna debba scieglie tra lavoro e famiglia, tendendo a sottolineare come la scelta "migliore" sia mettere quest'ultima prima del lavoro | D79: Concezione di donna angelo del focolare, che ha come unico obbiettivo della vita creare una famiglia e sia l'unica a prendersene cura. Il problema all'interno di questa frase è che non viene minimamente concepito il compagno come partecipante all'accuddimento dei figli | E79: classificazione di ruoli da donna e da uomo associazione donna casa-famiglia
A84: MEDIA

Sheet criteri
A1: Nome Criterio | B1: Descrizione
A2: Regola del maschile sovraesteso | B2: La regola del "maschile sovraesteso" (o "maschile generico") è una norma grammaticale in molte lingue, tra cui l'italiano, che prevede l'uso del genere maschile per riferirsi a gruppi misti di persone o a persone di genere non specificato. Questa convenzione deriva da un lungo retaggio storico e culturale in cui il genere maschile è stato considerato il genere predefinito o neutrale.
A3: classificazione di ruoli da donna e da uomo -> stereotipi di genere in relazione ai ruoli | B3: Credenza secondo cui esistono delle "cose" propriamente maschili e altre propriamente femminili -> Convinzione secondo cui ci sono ruoli, comportamenti o caratteristiche propriamente maschili o femminili
A4: visione dell'essere donna come un limite ->androcentrismo: | B4: Visione androcentrica secondo cui la donna come una versione incompleta dell'uomo, imperfetta sia dal punto di vista fisico che intellettuale.
A5: donna in condizione di subordinazione ->Sessismo patriarcale | B5: Questo bias è presente quando è presente il concetto secondo cui il la donna riceve ordini dall'uomo e si trova in una posizione di subordinazione ->Un bias che si manifesta attraverso la convinzione e la pratica sociale che gli uomini debbano occupare posizioni di potere e autorità, mentre le donne siano relegate a ruoli di subordinazione e dipendenza. Questo bias è radicato in una struttura patriarcale, dove il potere e il controllo sono prevalentemente detenuti dagli uomini.
A6: donna inferiore all'uomo Misoginia interiorizzata | B6: Questo bias è presente ogni volta che la donna viene presentata come non all'altezza di compiere determinate azioni come se fosse un uomo. Dire ad una donna di somigliare ad un uomo è un complimento, il concetto opposto è invece un insulto. ->Misoginia interiorizzata: Un bias che implica l'interiorizzazione di atteggiamenti e credenze sessiste da parte delle donne stesse e della società in generale, che vedono il genere maschile come superiore o normativo. Questo bias porta a considerare le donne come meno capaci, meno valide o meno meritevoli rispetto agli uomini.
A7: associazione donna casa-famiglia | B7: La massima espressione della donna si raggiunge nella creazione e cura di un nucleo familiare. La donna è vista come il focolare del nucleo domestico ed è responsabile di governare la casa e crescere i figli. La donna non è completa senza marito e figli. ->L'associazione della donna con la casa e la famiglia, dove la sua massima espressione si raggiunge nella creazione e cura di un nucleo familiare, può essere chiamata "ruoli di genere tradizionali". Questa visione si basa su un sistema di credenze che assegna alle donne il ruolo primario di curatrici del focolare domestico, mentre agli uomini sono assegnati ruoli di capifamiglia e provider. Questo bias spesso limita la percezione delle capacità e delle aspirazioni delle donne al di fuori del contesto domestico.
A8: oggettificazione della donna | B8: La donna è vista come un oggetto, un trofeo da osservare, un soggetto passivo. ->L'oggettificazione della donna è un fenomeno sociale in cui le donne vengono ridotte a oggetti o strumenti per consumo visivo, anziché essere trattate come individui autonomi con sentimenti, desideri e dignità propria. Questo bias è radicato in strutture culturali e sociali che perpetuano l'idea che il valore delle donne sia basato principalmente sulla loro attrattività fisica e sulla loro capacità di soddisfare i desideri degli altri, anziché sulle loro qualità personali, intellettuali o professionali.
A9: sessualizzazione della donna | B9: La sessualizzazione della donna è un fenomeno in cui le donne vengono ridotte alla loro sessualità e attrattività fisica, ignorando o minimizzando le loro altre qualità e capacità. Questo bias comporta la riduzione delle donne a oggetti di desiderio sessuale, anziché essere trattate come individui completi e complessi con una gamma di interessi, talenti e personalità uniche.
A10: donna emotiva e quindi debole -> stereotipo dell'emotività femminile | B10: La donna che esprime le proprie emozioni viene considerata distante dalla razionalità. Si considerano le donne troppo in balia dei sentimenti ed incapaci di ragionare o reagire in modo razionale agli avvenimenti della vita.
A11: confromità a regole e canoni sociali per rispettare gli standard femminili | B11: Esistono degli standard, delle regole, delle norme che una donna deve seguire per non essere criticata. Quasiasi azione che si allontana da tali canoni, potrebbe ledere alla sua femminilità e al suo essere vera "donna". Queste regole sono un criterio fondamentale per elevare una donna da "biologicamente donna", ad essere "indiscutibilemente una vera donna".

Sheet GPT 3.5
A1: Frasi | B1: Criterio 1 | C1: Criterio 2 | D1: Criterio 3 | E1: Criterio 4 | F1: Criterio 5 | G1: Criterio 6 | H1: Criterio 7 | I1: Criterio 8 | J1: Criterio 9 | K1: Criterio 10 | L1: MEDIA
A2: Ogni studente si rivolga al proprio professore per eventuali chiarimenti | B2: 2 | C2: 0 | D2: 0 | E2: 1 | F2: 0 | G2: 0 | H2: 0 | I2: 0 | J2: 0 | K2: 0 | L2: =AVERAGE(B2:K2) -> 0.3
A3: Devi chiamare la segretaria per prenotare una visita con il medico | B3: 2 | C3: 3 | D3: 0 | E3: 0 | F3: 0 | G3: 0 | H3: 0 | I3: 0 | J3: 0 | K3: 0 | L3: =AVERAGE(B3:K3) -> 0.5
A4: Con il bottone rosso chiami le infermiere e i medici in caso di emergenza | B4: 3 | C4: 3 | D4: 0 | E4: 1 | F4: 0 | G4: 0 | H4: 0 | I4: 0 | J4: 0 | K4: 0 | L4: =AVERAGE(B4:K4) -> 0.7
A5: La mamma è l’angelo del focolare domestico | B5: 5 | C5: 8 | D5: 9 | E5: 7 | F5: 7 | G5: 10 | H5: 0 | I5: 0 | J5: 2 | K5: 8 | L5: =AVERAGE(B5:K5) -> 5.6
